<?xml version="1.0" ?>
<robot name="mini_cheetah" xmlns:xacro="http://ros.org/wiki/xacro">
    <link name="body">
        <inertial>
            <mass value="4.832"/>
            <origin xyz="0.0 0.0 0.0"/>
            <inertia ixx="0.01647712" ixy="0" ixz="0" iyy="0.06248052" iyz="0" izz="0.070325813"/>
        </inertial>
        <visual>
            <geometry>
                <mesh filename="meshes/mini_vision_body.dae"/>
            </geometry>
            <origin rpy="0.0 0.0 0.0" xyz="0.0 0.0 0.0"/>
        </visual>
        <collision>
            <geometry>
                <box size="0.244 0.18 0.044"/>
            </geometry>
            <origin rpy="0 0 0" xyz="0 0 0"/>
        </collision>
    </link>
    <joint name="abduct_fr_rotor_j" type="fixed">
        <parent link="body"/>
        <child link="abduct_fr_rotor"/>
        <origin xyz="0.14775 -0.049 0.0"/>
    </joint>
    <link name="abduct_fr_rotor">
        <inertial>
            <mass value="0.055"/>
            <origin xyz="0.0 0.0 0.0"/>
            <inertia ixx="0.000141" ixy="0.0" ixz="0.0" iyy="0.000033" iyz="0.0" izz="0.000033"/>
        </inertial>
    </link>
    <joint name="abduct_fl_rotor_j" type="fixed">
        <parent link="body"/>
        <child link="abduct_fl_rotor"/>
        <origin xyz="0.14775 0.049 0.0"/>
    </joint>
    <link name="abduct_fl_rotor">
        <inertial>
            <mass value="0.055"/>
            <origin xyz="0.0 0.0 0.0"/>
            <inertia ixx="0.000141" ixy="0.0" ixz="0.0" iyy="0.000033" iyz="0.0" izz="0.000033"/>
        </inertial>
    </link>
    <joint name="abduct_hr_rotor_j" type="fixed">
        <parent link="body"/>
        <child link="abduct_hr_rotor"/>
        <origin xyz="-0.14775 -0.049 0.0"/>
    </joint>
    <link name="abduct_hr_rotor">
        <inertial>
            <mass value="0.055"/>
            <origin xyz="0.0 0.0 0.0"/>
            <inertia ixx="0.000141" ixy="0.0" ixz="0.0" iyy="0.000033" iyz="0.0" izz="0.000033"/>
        </inertial>
    </link>
    <joint name="abduct_hl_rotor_j" type="fixed">
        <parent link="body"/>
        <child link="abduct_hl_rotor"/>
        <origin xyz="-0.14775 0.049 0.0"/>
    </joint>
    <link name="abduct_hl_rotor">
        <inertial>
            <mass value="0.055"/>
            <origin xyz="0.0 0.0 0.0"/>
            <inertia ixx="0.000141" ixy="0.0" ixz="0.0" iyy="0.000033" iyz="0.0" izz="0.000033"/>
        </inertial>
    </link>

    <!--!!!!!!!!!!!! Front Right Leg !!!!!!!!!!!!!!!!!!!!!!!!!!!!!!!!!!!!-->
    <joint name="torso_to_abduct_fr_j" type="revolute">
        <axis xyz="1 0 0"/>
        <origin rpy="0 0 0" xyz="0.14775 -0.049 0.0"/>
        <parent link="body"/>
        <child link="abduct_fr"/>
        <limit effort="17" lower="-1.5" upper="1.5" velocity="40"/>
        <dynamics rotor_inertia="5076e-6" damping=".01"/>
    </joint>
    <link name="abduct_fr">
        <inertial>
            <mass value="0.54"/>
            <origin xyz="0.055 -0.0 0."/>
            <inertia ixx="0.000381" ixy="0.000058" ixz="0.00000045" 
                iyy="0.000560" iyz="0.00000095" izz="0.000444"/>
        </inertial>
        <visual>
            <geometry>
                <mesh filename="meshes/mini_abad.obj"/>
            </geometry>
            <origin rpy="3.141592 0.0 1.5708" xyz="0 0.0 0.0"/>
        </visual>
        <collision>
            <geometry>
                <cylinder radius="0.048" length="0.022"/>
            </geometry>
            <origin rpy="3.141592 1.5708 0.0" xyz="-0.01475 0 0"/>
        </collision>
    </link>
    <joint name="thigh_fr_rotor_j" type="fixed">
        <parent link="abduct_fr"/>
        <child link="thigh_fr_rotor"/>
        <origin xyz="0.055 -0.019 0.00"/>
    </joint>
    <link name="thigh_fr_rotor">
        <inertial>
            <mass value="0.055"/>
            <origin xyz="0.0 0.0 0.0"/>
            <inertia ixx="0.000033" ixy="0.0" ixz="0.0" iyy="0.000141" iyz="0.0" izz="0.000033"/>
        </inertial>
    </link>

    <joint name="abduct_fr_to_thigh_fr_j" type="revolute">
        <axis xyz="0 -1 0"/>
        <origin rpy="0.0 0.0 0.0" xyz="0.055 -0.019 0.00"/>
        <parent link="abduct_fr"/>
        <child link="thigh_fr"/>
        <limit effort="17" lower="-5." upper="5." velocity="40"/>
        <dynamics rotor_inertia="5076e-6" damping=".01"/>
    </joint>
    <link name="thigh_fr">
        <inertial>
            <mass value="0.634"/>
            <origin xyz="0.0 -0.032 -0.02"/>
            <inertia ixx="0.001983" ixy="0.000245" ixz="0.000013"
                iyy="0.002103" iyz="0.0000015" izz="0.000408"/>
        </inertial>
        <visual>
            <geometry>
                <mesh filename="meshes/mini_upper_link.obj"/>
            </geometry>
            <origin rpy="0.0 -1.5708 0.0" xyz="0.0 -0.049 0.0"/>
        </visual>
        <collision>
            <geometry>
                <box size="0.025 0.025 0.22"/>
            </geometry>
            <origin rpy="0 0 0" xyz="0 -0.049 -0.105"/>
        </collision>
    </link>
    <joint name="shank_fr_rotor_j" type="fixed">
        <parent link="thigh_fr"/>
        <child link="shank_fr_rotor"/>
        <origin xyz="0.0 -0.049 0.0"/>
    </joint>
    <link name="shank_fr_rotor">
        <inertial>
            <mass value="0.055"/>
            <origin xyz="0.0 0.0 0.0"/>
            <inertia ixx="0.000033" ixy="0.0" ixz="0.0" iyy="0.000141" iyz="0.0" izz="0.000033"/>
        </inertial>
    </link>

    <joint name="thigh_fr_to_knee_fr_j" type="revolute">
        <axis xyz="0 -1 0"/>
        <origin rpy="0.0 0 0.0" xyz="0.0 -0.049 -0.2085"/>
        <parent link="thigh_fr"/>
        <child link="shank_fr"/>
        <limit effort="26" lower="-2.705259778" upper="2.705259778" velocity="40"/>
        <dynamics rotor_inertia="12274e-6" damping=".0.01555"/>
    </joint>
    <link name="shank_fr">
        <inertial>
            <mass value="0.183"/>
            <origin xyz="0.0 0.0 -0.063"/>
            <inertia ixx="0.000605" ixy="0" ixz="0.0" iyy="0.000635" iyz="0" izz="0.000015"/>
        </inertial>
        <visual>
            <geometry>
                <mesh filename="meshes/mini_lower_link.obj"/>
            </geometry>
            <origin rpy="0.0 3.141592 0.0" xyz="0.0 0.0 0.0"/>
        </visual>
        <collision>
            <geometry>
                <box size="0.012 0.012 0.195"/>
            </geometry>
            <origin rpy="0 0 0" xyz="0 0 -0.0975"/>
        </collision>
    </link>

    <link name="toe_fr">
    <collision>
      <origin rpy="0 0 0" xyz="0 0 0"/>
      <geometry>
        <sphere radius="0.018"/>
      </geometry>
    </collision>
    <inertial>
      <mass value="0.0"/>
      <inertia ixx="0.0" ixy="0" ixz="0" iyy="0.0" iyz="0" izz="0.0"/>
    </inertial>
  </link>
  <joint name="toe_fr_joint" type="fixed">
    <parent link="shank_fr"/>
    <child link="toe_fr"/>
    <origin xyz="0 0 -0.195"/>
    <dynamics damping="0.0" friction="0.0"/>
  </joint>

<!--!!!!!!!!!!!! Front Left Leg !!!!!!!!!!!!!!!!!!!!!!!!!!!!!!!!!!!!-->
    <joint name="torso_to_abduct_fl_j" type="revolute">
        <axis xyz="1 0 0"/>
        <origin rpy="0 0 0" xyz="0.14775 0.049 0.0"/>
        <parent link="body"/>
        <child link="abduct_fl"/>
        <limit effort="17" lower="-1.5" upper="1.5" velocity="40"/>
        <dynamics rotor_inertia="5076e-6" damping=".01"/>
    </joint>
    <link name="abduct_fl">
        <inertial>
            <mass value="0.54"/>
            <origin xyz="0.055 0. 0."/>
            <inertia ixx="0.000381" ixy="0.000058" ixz="0.00000045"
                iyy="0.000560" iyz="0.00000095" izz="0.000444"/>
        </inertial>
        <visual>
            <geometry>
                <mesh filename="meshes/mini_abad.obj"/>
            </geometry>
            <origin rpy="0. 0. -1.5708" xyz="0.0 0.0 0.0"/>
        </visual>
        <collision>
            <geometry>
                <cylinder radius="0.048" length="0.022"/>
            </geometry>
            <origin rpy="0 1.5708 0" xyz="-0.01475 0 0"/>
        </collision>
    </link>
    <joint name="thigh_fl_rotor_j" type="fixed">
        <parent link="abduct_fl"/>
        <child link="thigh_fl_rotor"/>
        <origin xyz="0.055 0.019 0.00"/>
    </joint>
        <link name="thigh_fl_rotor">
        <inertial>
            <mass value="0.055"/>
            <origin xyz="0.0 0.0 0.0"/>
            <inertia ixx="0.000033" ixy="0.0" ixz="0.0" iyy="0.000141" iyz="0.0" izz="0.000033"/>
        </inertial>
    </link>

    <joint name="abduct_fl_to_thigh_fl_j" type="revolute">
        <axis xyz="0 -1 0"/>
        <origin rpy="0.0 0.0 0.0" xyz="0.055 0.019 0.00"/>
        <parent link="abduct_fl"/>
        <child link="thigh_fl"/>
        <limit effort="17" lower="-5." upper="5." velocity="40"/>
        <dynamics rotor_inertia="5076e-6" damping=".01"/>
    </joint>
    <link name="thigh_fl">
        <inertial>
            <mass value="0.634"/>
            <origin xyz="0.0 0.032 -0.02"/>
            <inertia ixx="0.001983" ixy="0.000245" ixz="0.000013"
                iyy="0.002103" iyz="0.0000015" izz="0.000408"/>
        </inertial>
        <visual>
            <geometry>
                <mesh filename="meshes/mini_upper_link.obj"/>
            </geometry>
            <origin rpy="0.0 -1.5708 0.0" xyz="0.0 0.049 0.0"/>
        </visual>
        <collision>
            <geometry>
                <box size="0.025 0.025 0.22"/>
            </geometry>
            <origin rpy="0 0 0" xyz="0 0.049 -0.105"/>
        </collision>
    </link>
    <joint name="shank_fl_rotor_j" type="fixed">
        <parent link="thigh_fl"/>
        <child link="shank_fl_rotor"/>
        <origin xyz="0 0.049 0"/>
    </joint>
    <link name="shank_fl_rotor">
        <inertial>
            <mass value="0.055"/>
            <origin xyz="0.0 0.0 0.0"/>
            <inertia ixx="0.000033" ixy="0.0" ixz="0.0" iyy="0.000141" iyz="0.0" izz="0.000033"/>
        </inertial>
    </link>

    <joint name="thigh_fl_to_knee_fl_j" type="revolute">
        <axis xyz="0 -1 0"/>
        <origin rpy="0.0 0 0.0" xyz="0.0 0.049 -0.2085"/>
        <parent link="thigh_fl"/>
        <child link="shank_fl"/>
        <limit effort="26" lower="-2.705259778" upper="2.705259778" velocity="40"/>
        <dynamics rotor_inertia="12274e-6" damping=".0.01555"/>
    </joint>
    <link name="shank_fl">
        <inertial>
            <mass value="0.183"/>
            <origin xyz="0.0 0.0 -0.063"/>
            <inertia ixx="0.000605" ixy="0" ixz="0.0" iyy="0.000635" iyz="0" izz="0.000015"/>
        </inertial>
        <visual>
            <geometry>
                <mesh filename="meshes/mini_lower_link.obj"/>
            </geometry>
            <origin rpy="0.0 3.141592 0.0" xyz="0.0 0.0 0.0"/>
        </visual>
        <collision>
            <geometry>
                <box size="0.012 0.012 0.195"/>
            </geometry>
            <origin rpy="0 3.141592 0" xyz="0 0 -0.0975"/>
        </collision>
    </link>


    <link name="toe_fl">
    <collision>
      <origin rpy="0 0 0" xyz="0 0 0"/>
      <geometry>
        <sphere radius="0.018"/>
      </geometry>
    </collision>
    <inertial>
      <mass value="0.0"/>
      <inertia ixx="0.0" ixy="0" ixz="0" iyy="0.0" iyz="0" izz="0.0"/>
    </inertial>
  </link>
  <joint name="toe_fl_joint" type="fixed">
    <parent link="shank_fl"/>
    <child link="toe_fl"/>
    <origin xyz="0 0 -0.195"/>
    <dynamics damping="0.0" friction="0.0"/>
  </joint>


<!--!!!!!!!!!!!! Hind Right Leg !!!!!!!!!!!!!!!!!!!!!!!!!!!!!!!!!!!!-->
    <joint name="torso_to_abduct_hr_j" type="revolute">
        <axis xyz="1 0 0"/>
        <origin rpy="0 0 0" xyz="-0.14775 -0.049 0.0"/>
        <parent link="body"/>
        <child link="abduct_hr"/>
        <limit effort="17" lower="-1.5" upper="1.5" velocity="40"/>
        <dynamics rotor_inertia="5076e-6" damping=".01"/>
    </joint>
    <link name="abduct_hr">
        <inertial>
            <mass value="0.54"/>
            <origin xyz="-0.055 -0.0 0."/>
            <inertia ixx="0.000381" ixy="0.000058" ixz="0.00000045"
                iyy="0.000560" iyz="0.00000095" izz="0.000444"/>
        </inertial>
        <visual>
            <geometry>
                <mesh filename="meshes/mini_abad.obj"/>
            </geometry>
            <origin rpy="0.0 0.0 1.5708" xyz="0.0 0.0 0.0"/>
        </visual>
        <collision>
            <geometry>
                <cylinder radius="0.048" length="0.022"/>
            </geometry>
            <origin rpy="0 -1.5708 0" xyz="0.01475 0 0"/>
        </collision>
    </link>
    <joint name="thigh_hr_rotor_j" type="fixed">
        <parent link="abduct_hr"/>
        <child link="thigh_hr_rotor"/>
        <origin xyz="-0.055 -0.019 0.00"/>
    </joint>
    <link name="thigh_hr_rotor">
        <inertial>
            <mass value="0.055"/>
            <origin xyz="0.0 0.0 0.0"/>
            <inertia ixx="0.000033" ixy="0.0" ixz="0.0" iyy="0.000141" iyz="0.0" izz="0.000033"/>
        </inertial>
    </link>

    <joint name="abduct_hr_to_thigh_hr_j" type="revolute">
        <axis xyz="0 -1 0"/>
        <origin rpy="0.0 0 0.0" xyz="-0.055 -0.019 0.00"/>
        <parent link="abduct_hr"/>
        <child link="thigh_hr"/>
        <limit effort="17" lower="-5." upper="5." velocity="40"/>
        <dynamics rotor_inertia="5076e-6" damping=".01"/>
    </joint>
    <link name="thigh_hr">
        <inertial>
            <mass value="0.634"/>
            <origin xyz="0.0 -0.032 -0.02"/>
            <inertia ixx="0.001983" ixy="0.000245" ixz="0.000013"
                iyy="0.002103" iyz="0.0000015" izz="0.000408"/>
        </inertial>
        <visual>
            <geometry>
                <mesh filename="meshes/mini_upper_link.obj"/>
            </geometry>
            <origin rpy="0.0 -1.5708 0.0" xyz="0.0 -0.049 0.0"/>
        </visual>
        <collision>
            <geometry>
                <box size="0.025 0.025 0.22"/>
            </geometry>
            <origin rpy="0 0 0" xyz="0 -0.049 -0.105"/>
        </collision>
    </link>
    <joint name="shank_hr_rotor_j" type="fixed">
        <parent link="thigh_hr"/>
        <child link="shank_hr_rotor"/>
        <origin xyz="0 -0.049 0"/>
    </joint>
    <link name="shank_hr_rotor">
        <inertial>
            <mass value="0.055"/>
            <origin xyz="0.0 0.0 0.0"/>
            <inertia ixx="0.000033" ixy="0.0" ixz="0.0" iyy="0.000141" iyz="0.0" izz="0.000033"/>
        </inertial>
    </link>

    <joint name="thigh_hr_to_knee_hr_j" type="revolute">
        <axis xyz="0 -1 0"/>
        <origin rpy="0.0 0 0.0" xyz="0.0 -0.049 -0.2085"/>
        <parent link="thigh_hr"/>
        <child link="shank_hr"/>
        <limit effort="26" lower="-2.705259778" upper="2.705259778" velocity="40"/>
        <dynamics rotor_inertia="12274e-6" damping=".0.01555"/>
    </joint>
    <link name="shank_hr">
        <inertial>
            <mass value="0.183"/>
            <origin xyz="0.0 0.0 -0.063"/>
            <inertia ixx="0.000605" ixy="0" ixz="0.0" iyy="0.000635" iyz="0" izz="0.000015"/>
        </inertial>
        <visual>
            <geometry>
                <mesh filename="meshes/mini_lower_link.obj"/>
            </geometry>
            <origin rpy="0.0 3.141592 0.0" xyz="0.0 0.0 0.0"/>
        </visual>
        <collision>
            <geometry>
                <box size="0.012 0.012 0.195"/>
            </geometry>
            <origin rpy="0 3.141592 0" xyz="0 0 -0.0975"/>
        </collision>
    </link>

     <link name="toe_hr">
    <collision>
      <origin rpy="0 0 0" xyz="0 0 0"/>
      <geometry>
        <sphere radius="0.018"/>
      </geometry>
    </collision>
    <inertial>
      <mass value="0.0"/>
      <inertia ixx="0.0" ixy="0" ixz="0" iyy="0.0" iyz="0" izz="0.0"/>
    </inertial>
  </link>
  <joint name="toe_hr_joint" type="fixed">
    <parent link="shank_hr"/>
    <child link="toe_hr"/>
    <origin xyz="0 0 -0.195"/>
    <dynamics damping="0.0" friction="0.0"/>
  </joint>


<!--!!!!!!!!!!!! Hind Left Leg !!!!!!!!!!!!!!!!!!!!!!!!!!!!!!!!!!!!-->
    <joint name="torso_to_abduct_hl_j" type="revolute">
        <axis xyz="1 0 0"/>
        <origin rpy="0 0 0" xyz="-0.14775 0.049 0.0"/>
        <parent link="body"/>
        <child link="abduct_hl"/>
        <limit effort="17" lower="-1.5" upper="1.5" velocity="40"/>
        <dynamics rotor_inertia="5076e-6" damping=".01"/>
    </joint>
    <link name="abduct_hl">
        <inertial>
            <mass value="0.54"/>
            <origin xyz="-0.055 0.0 0."/>
            <inertia ixx="0.000381" ixy="0.000058" ixz="0.00000045"
                iyy="0.000560" iyz="0.00000095" izz="0.000444"/>
        </inertial>
        <visual>
            <geometry>
                <mesh filename="meshes/mini_abad.obj"/>
            </geometry>
            <origin rpy="3.141592 0.0 -1.5708" xyz="0.0 0.0 0.0"/>
        </visual>
        <collision>
            <geometry>
                <cylinder radius="0.048" length="0.022"/>
            </geometry>
            <origin rpy="0 1.5708 0" xyz="0.01475 0 0"/>
        </collision>
    </link>
    <joint name="thigh_hl_rotor_j" type="fixed">
        <parent link="abduct_hl"/>
        <child link="thigh_hl_rotor"/>
        <origin xyz="-0.055 0.019 0.00"/>
    </joint>
    <link name="thigh_hl_rotor">
        <inertial>
            <mass value="0.055"/>
            <origin xyz="0.0 0.0 0.0"/>
            <inertia ixx="0.000033" ixy="0.0" ixz="0.0" iyy="0.000141" iyz="0.0" izz="0.000033"/>
        </inertial>
    </link>

    <joint name="abduct_hl_to_thigh_hl_j" type="revolute">
        <axis xyz="0 -1 0"/>
        <origin rpy="0.0 0 0.0" xyz="-0.055 0.019 0.00"/>
        <parent link="abduct_hl"/>
        <child link="thigh_hl"/>
        <limit effort="17" lower="-5." upper="5." velocity="40"/>
        <dynamics rotor_inertia="5076e-6" damping=".01"/>
    </joint>
    <link name="thigh_hl">
        <inertial>
            <mass value="0.634"/>
            <origin xyz="0.0 0.032 -0.02"/>
            <inertia ixx="0.001983" ixy="0.000245" ixz="0.000013" 
                iyy="0.002103" iyz="0.0000015" izz="0.000408"/>
        </inertial>
        <visual>
            <geometry>
                <mesh filename="meshes/mini_upper_link.obj"/>
            </geometry>
            <origin rpy="0.0 -1.5708 0.0" xyz="0.0 0.049 0.0"/>
        </visual>
        <collision>
            <geometry>
                <box size="0.025 0.025 0.22"/>
            </geometry>
            <origin rpy="0 0 0" xyz="0 0.049 -0.105"/>
        </collision>
    </link>
    <joint name="shank_hl_rotor_j" type="fixed">
        <parent link="thigh_hl"/>
        <child link="shank_hl_rotor"/>
        <origin xyz="0 0.049 0"/>
    </joint>
    <link name="shank_hl_rotor">
        <inertial>
            <mass value="0.055"/>
            <origin xyz="0.0 0.0 0.0"/>
            <inertia ixx="0.000033" ixy="0.0" ixz="0.0" iyy="0.000141" iyz="0.0" izz="0.000033"/>
        </inertial>
    </link>

    <joint name="thigh_hl_to_knee_hl_j" type="revolute">
        <axis xyz="0 -1 0"/>
        <origin rpy="0.0 0 0.0" xyz="0.0 0.049 -0.2085"/>
        <parent link="thigh_hl"/>
        <child link="shank_hl"/>
        <limit effort="26" lower="-2.705259778" upper="2.705259778" velocity="40"/>
        <dynamics rotor_inertia="12274e-6" damping=".0.01555"/>
    </joint>
    <link name="shank_hl">
        <inertial>
            <mass value="0.183"/>
            <origin xyz="0.0 0.0 -0.063"/>
            <inertia ixx="0.000605" ixy="0" ixz="0.0" iyy="0.000635" iyz="0" izz="0.000015"/>
        </inertial>
        <visual>
            <geometry>
                <mesh filename="meshes/mini_lower_link.obj"/>
            </geometry>
            <origin rpy="0.0 3.141592 0.0" xyz="0.0 0.0 0.0"/>
        </visual>
        <collision>
            <geometry>
                <box size="0.012 0.012 0.195"/>
            </geometry>
            <origin rpy="0 3.141592 0" xyz="0 0 -0.0975"/>
        </collision>
    </link>

    <link name="toe_hl">
    <collision>
      <origin rpy="0 0 0" xyz="0 0 0"/>
      <geometry>
        <sphere radius="0.018"/>
      </geometry>
    </collision>
    <inertial>
      <mass value="0.0"/>
      <inertia ixx="0.0" ixy="0" ixz="0" iyy="0.0" iyz="0" izz="0.0"/>
    </inertial>
  </link>
  <joint name="toe_hl_joint" type="fixed">
    <parent link="shank_hl"/>
    <child link="toe_hl"/>
    <origin xyz="0 0 -0.195"/>
    <dynamics damping="0.0" friction="0.0"/>
  </joint>

</robot>
